<?xml version='1.0'?>

<robot name="duckiebot" xmlns:xacro="http://www.ros.org/wiki/xacro">

  <material name="black">
    <color rgba="0.0 0.0 0.0 1.0"/>
  </material>

  <material name="red">
    <color rgba="0.8 0.0 0.0 1.0"/>
  </material>

  <pose>0 0 0 0 0 0</pose>

  <link name="car">
    <visual name='chassis_visual'>
      <origin xyz="0 0 0" rpy=" 0 0 0"/>
      <geometry>
        <mesh filename="package://duckietown-intnav/config/meshes/duckiebotFrame.dae"/>
      </geometry>
      <material name="red"/>
    </visual>
  </link>

  <link name="left_wheel">
    <origin xyz="0 0 0" rpy="0 0 0"/>
    <visual name="left_wheel_visual">
      <origin xyz="0 0 0" rpy="0 0 0"/>
      <geometry>
        <mesh filename="package://duckietown-intnav/config/meshes/duckiebot_leftwheel.dae"/>      
      </geometry>
      <material name="black"/>

    </visual>
  </link>

  <link name="right_wheel">
    <origin xyz="0 0 0" rpy="0 0 0"/>
    <visual name="right_wheel_visual">
      <origin xyz="0 0 0" rpy="0 0 0"/>
      <geometry>
        <mesh filename="package://duckietown-intnav/config/meshes/duckiebot_rightwheel.dae"/>    
      </geometry>
      <material name="black"/>
    </visual>
  </link>

  <joint type="continuous" name="left_wheel_hinge">
    <origin xyz="0.0 0 0" rpy="0 0 0"/>
    <child link="left_wheel"/>
    <parent link="car"/>
    <axis xyz="0 0 0" rpy="0 0 0"/>
  </joint>

  <joint type="continuous" name="right_wheel_hinge">
    <origin xyz="0.0 0 0" rpy="0 0 0"/>
    <child link="right_wheel"/>
    <parent link="car"/>
    <axis xyz="0 0 0" rpy="0 0 0"/>
  </joint>

  <link name="duckie">
    <visual name='chassis_visual'>
      <origin xyz="0 0 0" rpy="1.57079633 0 0"/>
      <geometry>
        <mesh filename="package://duckietown-intnav/config/meshes/duck.dae" scale="0.0005 0.0005 0.0005"/>
      </geometry>
      <material name="red"/>
    </visual>
  </link>

  <joint type="continuous" name="duckie_hinge">
    <origin xyz="0.0 0 0" rpy="0 0 0"/>
    <child link="duckie"/>
    <parent link="car"/>
    <axis xyz="0 0 0" rpy="0 0 0"/>
  </joint>

</robot>